<mujoco model="left_shadow_hand">
  <default>
    <default class="left_hand">
      <mesh scale="0.001 0.001 0.001"/>
      <joint axis="1 0 0" damping="0.05" armature="0.0002"/>
      <position forcerange="-1 1"/>

      <default class="lh_wrist">
        <joint damping="0.5"/>
        <default class="lh_wrist_y">
          <joint axis="0 -1 0" range="-0.523599 0.174533"/>
          <position kp="10" ctrlrange="-0.523599 0.174533" forcerange="-10 10"/>
        </default>
        <default class="lh_wrist_x">
          <joint range="-0.698132 0.488692"/>
          <position kp="8" ctrlrange="-0.698132 0.488692" forcerange="-5 5"/>
        </default>
      </default>

      <default class="lh_thumb">
        <default class="lh_thbase">
          <joint axis="0 0 1" range="-1.0472 1.0472"/>
          <position kp="0.4" ctrlrange="-1.0472 1.0472" forcerange="-3 3"/>
        </default>
        <default class="lh_thproximal">
          <joint axis="-1 0 0" range="0 1.22173"/>
          <position ctrlrange="0 1.22173" forcerange="-2 2"/>
        </default>
        <default class="lh_thhub">
          <joint axis="-1 0 0" range="-0.20944 0.20944"/>
          <position kp="0.5" ctrlrange="-0.20944 0.20944"/>
        </default>
        <default class="lh_thmiddle">
          <joint axis="0 -1 0" range="-0.698132 0.698132"/>
          <position kp="1.5" ctrlrange="-0.698132 0.698132"/>
        </default>
        <default class="lh_thdistal">
          <joint range="-0.261799 1.5708"/>
          <position ctrlrange="-0.261799 1.5708"/>
        </default>
      </default>

      <default class="lh_metacarpal">
        <joint axis="0.573576 0 0.819152" range="0 0.785398"/>
        <position ctrlrange="0 0.785398"/>
      </default>
      <default class="lh_knuckle">
        <joint axis="0 -1 0" range="-0.349066 0.349066"/>
        <position ctrlrange="-0.349066 0.349066"/>
      </default>
      <default class="lh_proximal">
        <joint range="-0.261799 1.5708"/>
        <position ctrlrange="-0.261799 1.5708"/>
      </default>
      <default class="lh_middle_distal">
        <joint range="0 1.5708"/>
        <position kp="0.5" ctrlrange="0 3.1415"/>
      </default>

      <default class="lh_plastic">
        <geom solimp="0.5 0.99 0.0001" solref="0.005 1"/>
        <default class="lh_plastic_visual">
          <geom type="mesh" material="black" contype="0" conaffinity="0" group="2"/>
        </default>
        <default class="lh_plastic_collision">
          <geom group="3" contype="0" conaffinity="0"/>
        </default>
      </default>
    </default>
  </default>

  <asset>
    <material name="black" specular="0.5" shininess="0.25" rgba="0.16355 0.16355 0.16355 1"/>
    <material name="gray" specular="0.0" shininess="0.25" rgba="0.80848 0.80848 0.80848 1"/>
    <material name="metallic" specular="0" shininess="0.25" rgba="0.9 0.9 0.9 1"/>

    <mesh name="lh_forearm_0" class="left_hand" file="forearm_0.obj"/>
    <mesh name="lh_forearm_1" class="left_hand" file="forearm_1.obj"/>
    <mesh name="lh_forearm_collision" class="left_hand" file="forearm_collision.obj"/>
    <mesh name="lh_wrist" class="left_hand" file="wrist.obj" scale="-0.001 0.001 0.001"/>
    <mesh name="lh_palm" class="left_hand" file="palm.obj" scale="-0.001 0.001 0.001"/>
    <mesh name="lh_f_knuckle" class="left_hand" file="f_knuckle.obj"/>
    <mesh name="lh_f_proximal" class="left_hand" file="f_proximal.obj"/>
    <mesh name="lh_f_middle" class="left_hand" file="f_middle.obj"/>
    <mesh name="lh_f_distal_pst" class="left_hand" file="f_distal_pst.obj"/>
    <mesh name="lh_f_distal_pst_214" class="left_hand" file="f_distal_pst_214.obj"/>
    <mesh name="lh_lf_metacarpal" class="left_hand" file="lf_metacarpal.obj" scale="-0.001 0.001 0.001"/>
    <mesh name="lh_th_proximal" class="left_hand" file="th_proximal.obj"/>
    <mesh name="lh_th_middle" class="left_hand" file="th_middle.obj"/>
    <mesh name="lh_th_distal_pst" class="left_hand" file="th_distal_pst.obj"/>
    <mesh name="lh_th_distal_pst_190" class="left_hand" file="th_distal_pst_190.obj"/>
  </asset>

  <worldbody>
    <body name="lh_forearm" childclass="left_hand" quat="-1 -1 1 1" pos="0.4 -0.15 0.13" gravcomp="1">
      <inertial mass="3" pos="0 0 0.09" diaginertia="0.0138 0.0138 0.00744"/>
      <joint type="slide" name="lh_forearm_y" axis="0 0 1" stiffness="300" range="0.0 0.06" damping="67.47621803272617"/>
      <joint type="slide" name="lh_forearm_x" axis="-1 0 0" stiffness="300" range="-0.7605 0.4605" damping="67.47621803272617"/>
      <geom class="lh_plastic_visual" mesh="lh_forearm_0" material="gray"/>
      <geom class="lh_plastic_visual" mesh="lh_forearm_1"/>
      <geom class="lh_plastic_collision" type="capsule" margin="0.05" mesh="lh_forearm_collision" conaffinity="2" contype="2"/>
      <geom class="lh_plastic_collision" size="0.035 0.035 0.035" pos="0 -0.01 0.181" quat="0.924909 0 0.380188 0"
        type="box"/>
      <body name="lh_wrist" pos="0 -0.01 0.21301" gravcomp="1">
        <inertial mass="0.1" pos="0 0 0.029" quat="0.5 0.5 0.5 0.5" diaginertia="6.4e-05 4.38e-05 3.5e-05"/>
        <joint class="lh_wrist_y" name="lh_WRJ2"/>
        <geom class="lh_plastic_visual" mesh="lh_wrist" material="metallic"/>
        <geom size="0.0135 0.015" quat="0.499998 0.5 0.5 -0.500002" type="cylinder" class="lh_plastic_collision"/>
        <geom size="0.011 0.005" pos="0.026 0 0.034" quat="1 0 1 0" type="cylinder" class="lh_plastic_collision"/>
        <geom size="0.011 0.005" pos="-0.031 0 0.034" quat="1 0 1 0" type="cylinder" class="lh_plastic_collision"/>
        <geom size="0.0135 0.009 0.005" pos="0.021 0 0.011" quat="-0.923879 0 0.382684 0" type="box"
          class="lh_plastic_collision"/>
        <geom size="0.0135 0.009 0.005" pos="-0.026 0 0.01" quat="-0.923879 0 -0.382684 0" type="box"
          class="lh_plastic_collision"/>
        <body name="lh_palm" pos="0 0 0.034" gravcomp="1">
          <inertial mass="0.3" pos="0 0 0.035" quat="1 0 0 1" diaginertia="0.0005287 0.0003581 0.000191"/>
          <joint class="lh_wrist_x" name="lh_WRJ1"/>
          <geom class="lh_plastic_visual" mesh="lh_palm"/>
          <geom size="0.031 0.0035 0.049" pos="-0.011 0.0085 0.038" type="box" class="lh_plastic_collision"/>
          <geom size="0.018 0.0085 0.049" pos="0.002 -0.0035 0.038" type="box" class="lh_plastic_collision"/>
          <geom size="0.013 0.0085 0.005" pos="-0.029 -0.0035 0.082" type="box" class="lh_plastic_collision"/>
          <geom size="0.013 0.007 0.009" pos="-0.0265 -0.001 0.07" quat="0.987241 0.0990545 0.0124467 -0.124052"
            type="box" class="lh_plastic_collision"/>
          <geom size="0.0105 0.0135 0.012" pos="-0.0315 -0.0085 0.001" type="box" class="lh_plastic_collision"/>
          <geom size="0.011 0.0025 0.015" pos="-0.0125 -0.015 0.004" quat="-0.971338 0 0 -0.237703" type="box"
            class="lh_plastic_collision"/>
          <geom size="0.009 0.012 0.002" pos="-0.011 0 0.089" type="box" class="lh_plastic_collision"/>
          <geom size="0.01 0.012 0.02" pos="0.03 0 0.009" type="box" class="lh_plastic_collision"/>
          <body name="lh_thbase" pos="-0.034 -0.00858 0.029" quat="0 -0.382683 0 0.92388" gravcomp="1">
            <inertial mass="0.01" pos="0 0 0" diaginertia="1.6e-07 1.6e-07 1.6e-07"/>
            <geom class="lh_plastic_collision" size="0.013"/>
            <body name="lh_thproximal" gravcomp="1">
              <inertial mass="0.04" pos="0 0 0.019" diaginertia="1.36e-05 1.36e-05 3.13e-06"/>
              <joint name="lh_THJ4" class="lh_thproximal"/>
              <geom class="lh_plastic_visual" mesh="lh_th_proximal"/>
              <geom class="lh_plastic_collision" size="0.0105 0.009" pos="0 0 0.02" type="capsule"/>
              <body name="lh_thhub" pos="0 0 0.038" gravcomp="1">
                <inertial mass="0.005" pos="0 0 0" diaginertia="1e-06 1e-06 3e-07"/>
                <joint name="lh_THJ3" class="lh_thhub"/>
                <geom size="0.011" class="lh_plastic_collision"/>
                <body name="lh_thmiddle" gravcomp="1">
                  <inertial mass="0.02" pos="0 0 0.016" diaginertia="5.1e-06 5.1e-06 1.21e-06"/>
                  <joint name="lh_THJ2" class="lh_thmiddle" range="0.0 0.698132"/>
                  <geom class="lh_plastic_visual" mesh="lh_th_middle"/>
                  <geom size="0.009 0.009" pos="0 0 0.012" type="capsule" class="lh_plastic_collision" contype="1" conaffinity="1"/>
                  <geom size="0.01" pos="0 0 0.03" class="lh_plastic_collision"/>
                  <body name="lh_thdistal" pos="0 0 0.032" quat="1 0 0 -1" gravcomp="1">
                    <inertial mass="0.017" pos="0 0 0.0145588" quat="1 0 0 1"
                      diaginertia="2.37794e-06 2.27794e-06 1e-06"/>
                    <geom class="lh_plastic_visual" mesh="lh_th_distal_pst"/>
                    <geom class="lh_plastic_collision" type="capsule" mesh="lh_th_distal_pst_190" contype="1" conaffinity="1"/>
                    <site name="lh_thdistal_site" pos="0.0 0.0 0.0275" type="sphere" size="0.004" group="4" rgba="0 1 0 0.6"/>
                  </body>
                </body>
              </body>
            </body>
          </body>
          <body name="lh_ffknuckle" pos="-0.033 0 0.095" gravcomp="1">
            <inertial mass="0.008" pos="0 0 0" quat="0.5 0.5 -0.5 0.5" diaginertia="3.2e-07 2.6e-07 2.6e-07"/>
            <joint name="lh_FFJ4" class="lh_knuckle" axis="0 1 0"/>
            <geom pos="0 0 0.0005" class="lh_plastic_visual" mesh="lh_f_knuckle" material="metallic"/>
            <geom size="0.009 0.009" quat="1 0 1 0" type="cylinder" class="lh_plastic_collision"/>
            <body name="lh_ffproximal" gravcomp="1">
              <inertial mass="0.03" pos="0 0 0.0225" quat="1 0 0 1" diaginertia="1e-05 9.8e-06 1.8e-06"/>
              <joint name="lh_FFJ3" class="lh_proximal"/>
              <geom class="lh_plastic_visual" mesh="lh_f_proximal"/>
              <geom size="0.009 0.02" pos="0 0 0.025" type="capsule" class="lh_plastic_collision"/>
              <body name="lh_ffmiddle" pos="0 0 0.045" gravcomp="1">
                <inertial mass="0.017" pos="0 0 0.0125" quat="1 0 0 1" diaginertia="2.7e-06 2.6e-06 8.7e-07"/>
                <joint name="lh_FFJ2" class="lh_middle_distal"/>
                <geom class="lh_plastic_visual" mesh="lh_f_middle"/>
                <geom size="0.009 0.0125" pos="0 0 0.0125" type="capsule" class="lh_plastic_collision"/>
                <body name="lh_ffdistal" pos="0 0 0.025" gravcomp="1">
                  <inertial mass="0.013" pos="0 0 0.0130769" quat="1 0 0 1"
                    diaginertia="1.28092e-06 1.12092e-06 5.3e-07"/>
                  <site name="lh_ffdistal_site" pos="0.0 0.0 0.026" type="sphere" size="0.004" group="4" rgba="0 1 0 0.6"/>
                  <joint name="lh_FFJ1" class="lh_middle_distal"/>
                  <geom class="lh_plastic_visual" mesh="lh_f_distal_pst"/>
                  <geom class="lh_plastic_collision" type="capsule" mesh="lh_f_distal_pst_214" contype="1" conaffinity="1"/>
                </body>
              </body>
            </body>
          </body>
          <body name="lh_mfknuckle" pos="-0.011 0 0.099" gravcomp="1">
            <inertial mass="0.008" pos="0 0 0" quat="0.5 0.5 -0.5 0.5" diaginertia="3.2e-07 2.6e-07 2.6e-07"/>
            <joint name="lh_MFJ4" class="lh_knuckle" axis="0 1 0"/>
            <geom pos="0 0 0.0005" class="lh_plastic_visual" mesh="lh_f_knuckle" material="metallic"/>
            <geom size="0.009 0.009" quat="1 0 1 0" type="cylinder" class="lh_plastic_collision"/>
            <body name="lh_mfproximal" gravcomp="1">
              <inertial mass="0.03" pos="0 0 0.0225" quat="1 0 0 1" diaginertia="1e-05 9.8e-06 1.8e-06"/>
              <joint name="lh_MFJ3" class="lh_proximal"/>
              <geom class="lh_plastic_visual" mesh="lh_f_proximal"/>
              <geom size="0.009 0.02" pos="0 0 0.025" type="capsule" class="lh_plastic_collision"/>
              <body name="lh_mfmiddle" pos="0 0 0.045" gravcomp="1">
                <inertial mass="0.017" pos="0 0 0.0125" quat="1 0 0 1" diaginertia="2.7e-06 2.6e-06 8.7e-07"/>
                <joint name="lh_MFJ2" class="lh_middle_distal"/>
                <geom class="lh_plastic_visual" mesh="lh_f_middle"/>
                <geom size="0.009 0.0125" pos="0 0 0.0125" type="capsule" class="lh_plastic_collision"/>
                <body name="lh_mfdistal" pos="0 0 0.025" gravcomp="1">
                  <inertial mass="0.013" pos="0 0 0.0130769" quat="1 0 0 1"
                    diaginertia="1.28092e-06 1.12092e-06 5.3e-07"/>
                  <joint name="lh_MFJ1" class="lh_middle_distal"/>
                  <geom class="lh_plastic_visual" mesh="lh_f_distal_pst"/>
                  <geom class="lh_plastic_collision" type="capsule" mesh="lh_f_distal_pst_214" contype="1" conaffinity="1"/>
                  <site name="lh_mfdistal_site" pos="0.0 0.0 0.026" type="sphere" size="0.004" group="4" rgba="0 1 0 0.6"/>
                </body>
              </body>
            </body>
          </body>
          <body name="lh_rfknuckle" pos="0.011 0 0.095" gravcomp="1">
            <inertial mass="0.008" pos="0 0 0" quat="0.5 0.5 -0.5 0.5" diaginertia="3.2e-07 2.6e-07 2.6e-07"/>
            <joint name="lh_RFJ4" class="lh_knuckle"/>
            <geom pos="0 0 0.0005" class="lh_plastic_visual" mesh="lh_f_knuckle" material="metallic"/>
            <geom size="0.009 0.009" quat="1 0 1 0" type="cylinder" class="lh_plastic_collision"/>
            <body name="lh_rfproximal" gravcomp="1">
              <inertial mass="0.03" pos="0 0 0.0225" quat="1 0 0 1" diaginertia="1e-05 9.8e-06 1.8e-06"/>
              <joint name="lh_RFJ3" class="lh_proximal"/>
              <geom class="lh_plastic_visual" mesh="lh_f_proximal"/>
              <geom size="0.009 0.02" pos="0 0 0.025" type="capsule" class="lh_plastic_collision"/>
              <body name="lh_rfmiddle" pos="0 0 0.045" gravcomp="1">
                <inertial mass="0.017" pos="0 0 0.0125" quat="1 0 0 1" diaginertia="2.7e-06 2.6e-06 8.7e-07"/>
                <joint name="lh_RFJ2" class="lh_middle_distal"/>
                <geom class="lh_plastic_visual" mesh="lh_f_middle"/>
                <geom size="0.009 0.0125" pos="0 0 0.0125" type="capsule" class="lh_plastic_collision"/>
                <body name="lh_rfdistal" pos="0 0 0.025" gravcomp="1">
                  <inertial mass="0.013" pos="0 0 0.0130769" quat="1 0 0 1"
                    diaginertia="1.28092e-06 1.12092e-06 5.3e-07"/>
                  <joint name="lh_RFJ1" class="lh_middle_distal"/>
                  <geom class="lh_plastic_visual" mesh="lh_f_distal_pst"/>
                  <geom class="lh_plastic_collision" type="capsule" mesh="lh_f_distal_pst_214" contype="1" conaffinity="1"/>
                  <site name="lh_rfdistal_site" pos="0.0 0.0 0.026" type="sphere" size="0.004" group="4" rgba="0 1 0 0.6"/>
                </body>
              </body>
            </body>
          </body>
          <body name="lh_lfmetacarpal" pos="0.033 0 0.02071" gravcomp="1">
            <inertial mass="0.03" pos="0 0 0.04" quat="1 0 0 1" diaginertia="1.638e-05 1.45e-05 4.272e-06"/>
            <!-- <joint name="lh_LFJ5" class="lh_metacarpal" axis="0.573576 0 -0.819152"/> -->
            <geom class="lh_plastic_visual" mesh="lh_lf_metacarpal"/>
            <geom size="0.011 0.012 0.025" pos="-0.002 0 0.033" type="box" class="lh_plastic_collision"/>
            <body name="lh_lfknuckle" pos="0 0 0.06579" gravcomp="1">
              <inertial mass="0.008" pos="0 0 0" quat="0.5 0.5 -0.5 0.5" diaginertia="3.2e-07 2.6e-07 2.6e-07"/>
              <joint name="lh_LFJ4" class="lh_knuckle"/>
              <geom pos="0 0 0.0005" class="lh_plastic_visual" mesh="lh_f_knuckle" material="metallic"/>
              <geom size="0.009 0.009" quat="1 0 1 0" type="cylinder" class="lh_plastic_collision"/>
              <body name="lh_lfproximal" gravcomp="1">
                <inertial mass="0.03" pos="0 0 0.0225" quat="1 0 0 1" diaginertia="1e-05 9.8e-06 1.8e-06"/>
                <joint name="lh_LFJ3" class="lh_proximal"/>
                <geom class="lh_plastic_visual" mesh="lh_f_proximal"/>
                <geom size="0.009 0.02" pos="0 0 0.025" type="capsule" class="lh_plastic_collision"/>
                <body name="lh_lfmiddle" pos="0 0 0.045" gravcomp="1">
                  <inertial mass="0.017" pos="0 0 0.0125" quat="1 0 0 1" diaginertia="2.7e-06 2.6e-06 8.7e-07"/>
                  <joint name="lh_LFJ2" class="lh_middle_distal"/>
                  <geom class="lh_plastic_visual" mesh="lh_f_middle"/>
                  <geom size="0.009 0.0125" pos="0 0 0.0125" type="capsule" class="lh_plastic_collision"/>
                  <body name="lh_lfdistal" pos="0 0 0.025" gravcomp="1">
                    <inertial mass="0.013" pos="0 0 0.0130769" quat="1 0 0 1"
                      diaginertia="1.28092e-06 1.12092e-06 5.3e-07"/>
                    <joint name="lh_LFJ1" class="lh_middle_distal"/>
                    <geom class="lh_plastic_visual" mesh="lh_f_distal_pst"/>
                    <geom class="lh_plastic_collision" type="capsule" mesh="lh_f_distal_pst_214" contype="1" conaffinity="1"/>
                    <site name="lh_lfdistal_site" pos="0.0 0.0 0.026" type="sphere" size="0.004" group="4" rgba="0 1 0 0.6"/>
                  </body>
                </body>
              </body>
            </body>
          </body>
        </body>
      </body>
    </body>
  </worldbody>

  <contact>
    <exclude body1="lh_wrist" body2="lh_forearm"/>
    <exclude body1="lh_thproximal" body2="lh_thmiddle"/>
    <exclude body1="lh_thdistal" body2="lh_thmiddle"/>
    <exclude body1="lh_thdistal" body2="lh_mfdistal"/> 
    <exclude body1="lh_thdistal" body2="lh_rfdistal"/>
    <exclude body1="lh_thdistal" body2="lh_lfdistal"/>
    <exclude body1="lh_thmiddle" body2="lh_ffdistal"/>
    <exclude body1="lh_thmiddle" body2="lh_mfdistal"/>
    <exclude body1="lh_thmiddle" body2="lh_rfdistal"/>
    <exclude body1="lh_thmiddle" body2="lh_lfdistal"/> 
    <exclude body1="lh_ffdistal" body2="lh_rfdistal"/>
    <exclude body1="lh_ffdistal" body2="lh_lfdistal"/>
    <exclude body1="lh_mfdistal" body2="lh_lfdistal"/>
  </contact>

  <!-- <tendon>
    <fixed name="rh_FFJ0">
      <joint joint="rh_FFJ2" coef="1"/>
      <joint joint="rh_FFJ1" coef="1"/>
    </fixed>
    <fixed name="rh_MFJ0">
      <joint joint="rh_MFJ2" coef="1"/>
      <joint joint="rh_MFJ1" coef="1"/>
    </fixed>
    <fixed name="rh_RFJ0">
      <joint joint="rh_RFJ2" coef="1"/>
      <joint joint="rh_RFJ1" coef="1"/>
    </fixed>
    <fixed name="rh_LFJ0">
      <joint joint="rh_LFJ2" coef="1"/>
      <joint joint="rh_LFJ1" coef="1"/>
    </fixed>
  </tendon> -->

  <actuator>
    <position name="lh_A_FOJ2" joint="lh_forearm_y" ctrlrange="0.0 0.06" kp="300"/>
    <position name="lh_A_FOJ1" joint="lh_forearm_x" ctrlrange="-0.7605 0.4605" kp="300"/>

    <position name="lh_A_WRJ2" joint="lh_WRJ2" class="lh_wrist_y"/>
    <position name="lh_A_WRJ1" joint="lh_WRJ1" class="lh_wrist_x"/>
    <!-- <position name="lh_A_THJ5" joint="lh_THJ5" class="lh_thbase"/> -->
    <position name="lh_A_THJ4" joint="lh_THJ4" class="lh_thproximal"/>
    <position name="lh_A_THJ3" joint="lh_THJ3" class="lh_thhub"/>
    <position name="lh_A_THJ2" joint="lh_THJ2" class="lh_thmiddle" ctrlrange="0.0 0.698132"/>
    <!-- <position name="lh_A_THJ1" joint="lh_THJ1" class="lh_thdistal"/> -->
    <position name="lh_A_FFJ4" joint="lh_FFJ4" class="lh_knuckle"/>
    <position name="lh_A_FFJ3" joint="lh_FFJ3" class="lh_proximal"/>
    <position name="lh_A_FFJ2" joint="lh_FFJ2" class="lh_middle_distal"/>
    <position name="lh_A_FFJ1" joint="lh_FFJ1" class="lh_middle_distal"/>
    <position name="lh_A_MFJ4" joint="lh_MFJ4" class="lh_knuckle"/>
    <position name="lh_A_MFJ3" joint="lh_MFJ3" class="lh_proximal"/>
    <position name="lh_A_MFJ2" joint="lh_MFJ2" class="lh_middle_distal"/>
    <position name="lh_A_MFJ1" joint="lh_MFJ1" class="lh_middle_distal"/>
    <position name="lh_A_RFJ4" joint="lh_RFJ4" class="lh_knuckle"/>
    <position name="lh_A_RFJ3" joint="lh_RFJ3" class="lh_proximal"/>
    <position name="lh_A_RFJ2" joint="lh_RFJ2" class="lh_middle_distal"/>
    <position name="lh_A_RFJ1" joint="lh_RFJ1" class="lh_middle_distal"/>
    <!-- <position name="lh_A_LFJ5" joint="lh_LFJ5" class="lh_metacarpal"/> -->
    <position name="lh_A_LFJ4" joint="lh_LFJ4" class="lh_knuckle"/>
    <position name="lh_A_LFJ3" joint="lh_LFJ3" class="lh_proximal"/>
    <position name="lh_A_LFJ2" joint="lh_LFJ2" class="lh_middle_distal"/>
    <position name="lh_A_LFJ1" joint="lh_LFJ1" class="lh_middle_distal"/>

  </actuator>
</mujoco>